Workbook

Sheet Epics
A1: Epic ID | B1: Epic Name | C1: Description | D1: Business Value | E1: Implementation Status | F1: Entities Found | G1: Package Location | H1: Features Count | I1: Stories Count | J1: Tasks Count | K1: Story Points (Calculated) | L1: Priority | M1: Status
A2: E1 | B2: Financial Management – Budgeting, Incomes & Expenses | C2: Complete financial tracking system with budgets, expenses, incomes, multi-currency support, variance analysis, and financial reporting. Enables cost control and profitability tracking. | D2: Provides financial transparency, aids cost control, supports profitability analysis, enables budget vs actual comparison, supports executive decision-making with financial dashboards. | E2: PARTIAL | F2: CProjectIncomeType, CProjectIncome, CCurrency, CProjectExpense, CProjectExpenseType, CBudget, CBudgetType | G2: projectexpenses, projectincomes, budgets | H2: 4 | I2: 9 | J2: 27 | K2: =SUMIF(Features!B:B,A2,Features!I:I) | L2: HIGH | M2: PARTIAL
A3: E2 | B3: Resource & Timesheet Management | C3: Complete resource management with resource definition, availability calendars, allocation to activities, capacity planning, timesheet entry, and utilization reporting. | D3: Optimizes resource allocation, prevents overbooking, enables accurate cost tracking, improves capacity planning, supports data-driven resource decisions. | E3: TODO | F3: Not Implemented | G3: resources (missing), timesheets (missing) | H3: 3 | I3: 7 | J3: 21 | K3: =SUMIF(Features!B:B,A3,Features!I:I) | L3: HIGH | M3: TODO
A4: E3 | B4: Document & Attachment Management | C4: Secure file storage with upload/download, version control, auto document type detection, preview capabilities, and integration with all project entities. | D4: Centralizes project files, provides version history, reduces context switching, improves collaboration, ensures document security. | E4: DONE | F4: CAttachment, CDocumentType | G4: attachments, documenttypes | H4: 3 | I4: 5 | J4: 12 | K4: =SUMIF(Features!B:B,A4,Features!I:I) | L4: CRITICAL | M4: DONE
A5: E4 | B5: Reporting & Analytics | C5: Comprehensive analytics with agile metrics (burndown, velocity, CFD), financial dashboards, resource utilization reports, custom report builder, and scheduled exports. | D5: Provides actionable insights, supports data-driven decisions, enables performance tracking, facilitates executive reporting, improves team visibility. | E5: TODO | F5: Dashboard widgets exist (partial) | G5: dashboard (partial), reports (missing) | H5: 4 | I5: 10 | J5: 30 | K5: =SUMIF(Features!B:B,A5,Features!I:I) | L5: HIGH | M5: TODO
A6: E5 | B6: Portfolio & Program Management | C6: Strategic oversight across multiple projects with portfolio grouping, cross-project dependencies, consolidated dashboards, budget rollups, and executive reporting. | D6: Enables strategic alignment, balances resources across portfolio, provides executive visibility, manages cross-project dependencies, supports strategic planning. | E6: TODO | F6: Not Implemented | G6: portfolios (missing), programs (missing) | H6: 3 | I6: 8 | J6: 24 | K6: =SUMIF(Features!B:B,A6,Features!I:I) | L6: MEDIUM | M6: TODO
A7: E6 | B7: Idea & Backlog Management | C7: Innovation management with idea submission, stakeholder voting, prioritization, product backlog board, and transition from idea to feature. | D7: Captures stakeholder ideas, enables democratic prioritization, manages product backlog, supports innovation, aligns features with customer needs. | E7: TODO | F7: Not Implemented | G7: ideas (missing), backlog (partial - sprint backlog only) | H7: 2 | I7: 5 | J7: 15 | K7: =SUMIF(Features!B:B,A7,Features!I:I) | L7: MEDIUM | M7: TODO
A8: E7 | B8: Issue & Bug Tracking | C8: Dedicated bug tracking system with severity classification, reproduction steps, triage workflow, bug metrics, and integration with development workflow. | D8: Improves software quality, enables systematic bug resolution, supports triage process, provides defect metrics, integrates with development. | E8: PARTIAL | F8: CTicketType, CTicket | G8: tickets (needs enhancement) | H8: 3 | I8: 7 | J8: 21 | K8: =SUMIF(Features!B:B,A8,Features!I:I) | L8: MEDIUM | M8: PARTIAL
A9: E8 | B9: Calendar & Scheduling Integration | C9: Unified calendar view with meetings, sprints, milestones, drag-drop rescheduling, conflict detection, and external calendar integration (Google Calendar, Outlook). | D9: Reduces scheduling conflicts, improves coordination, provides unified schedule view, enables easy rescheduling, integrates with external calendars. | E9: TODO | F9: CMeeting, CSprint exist (no calendar view) | G9: calendar (missing) | H9: 2 | I9: 5 | J9: 15 | K9: =SUMIF(Features!B:B,A9,Features!I:I) | L9: MEDIUM | M9: TODO
A10: E9 | B10: Permissions & Role Management UI | C10: Administrative UI for role definition, permission assignment, user access control, permission schemes, and role-based access control (RBAC) configuration. | D10: Enables granular access control, reduces security risks, simplifies administration, supports compliance requirements, provides audit trail. | E10: TODO | F10: CRole exists (no UI) | G10: users (backend only) | H10: 2 | I10: 4 | J10: 12 | K10: =SUMIF(Features!B:B,A10,Features!I:I) | L10: LOW | M10: TODO
A11: E10 | B11: Client Portal & Stakeholder Collaboration | C11: External portal for clients and stakeholders with project status visibility, deliverable approval, feedback submission, and controlled access. | D11: Strengthens client relationships, provides transparency, enables client feedback, reduces email communication, improves stakeholder engagement. | E11: TODO | F11: Not Implemented | G11: stakeholders (missing), portal (missing) | H11: 2 | I11: 5 | J11: 15 | K11: =SUMIF(Features!B:B,A11,Features!I:I) | L11: LOW | M11: TODO
A12: E11 | B12: AI & Automation Features | C12: AI-powered features including intelligent recommendations, natural language summaries, predictive analytics, automated task assignment, and risk prediction. | D12: Enhances efficiency through automation, provides predictive insights, reduces manual work, supports proactive decision-making, improves accuracy. | E12: TODO | F12: Not Implemented | G12: ai (missing), automation (missing) | H12: 3 | I12: 7 | J12: 21 | K12: =SUMIF(Features!B:B,A12,Features!I:I) | L12: LOW | M12: TODO
A13: E12 | B13: Notifications & Integrations | C13: Multi-channel notifications (in-app, email, Slack, Teams) with preference management, real-time updates, webhook support, and third-party integrations. | D13: Keeps teams informed, reduces missed updates, enables integration with existing tools, supports flexible notification preferences, improves communication. | E13: PARTIAL | F13: CNotificationService exists (in-app only) | G13: notifications (partial) | H13: 3 | I13: 6 | J13: 18 | K13: =SUMIF(Features!B:B,A13,Features!I:I) | L13: MEDIUM | M13: PARTIAL
... A24: E23 | B24: Team & User Management | C24: Team creation, team member management, user profiles, user roles, team hierarchy, and user activity tracking. | D24: Organizes teams, manages members, assigns roles, tracks activity, provides team visibility, enables collaboration. | E24: DONE | F24: CTeam | G24: teams, users | H24: 3 | I24: 6 | J24: 15 | K24: =SUMIF(Features!B:B,A24,Features!I:I) | L24: CRITICAL | M24: DONE
A25: E5 | B25: Advanced Workflow Management | C25: Jira-like visual workflow designer with transitions, validators, conditions, post-functions, and screens | D25: HIGH | E25: TODO | K25: =SUMIF(Features!B:B,A25,Features!I:I)
A26: E6 | B26: Issue Linking & Dependencies | C26: Link issues with relationships like 'blocks', 'depends on', 'relates to', 'duplicates' | D26: HIGH | E26: TODO | K26: =SUMIF(Features!B:B,A26,Features!I:I)
A27: E5 | B27: Advanced Workflow Management | C27: Visual workflow designer with transitions, validators, conditions, post-functions, screens | D27: HIGH | E27: TODO | K27: =SUMIF(Features!B:B,A27,Features!I:I)
A28: E6 | B28: Issue Linking & Dependencies | C28: Link issues with relationships: blocks, depends on, relates to, duplicates, clones | D28: HIGH | E28: TODO | K28: =SUMIF(Features!B:B,A28,Features!I:I)
A29: E7 | B29: Advanced Kanban Features | C29: WIP limits, swimlanes, quick filters, cycle time, control charts | D29: HIGH | E29: TODO | K29: =SUMIF(Features!B:B,A29,Features!I:I)
A30: E8 | B30: Time Tracking & Worklog | C30: Track time spent, original estimate, remaining estimate with detailed work logs | D30: HIGH | E30: TODO | K30: =SUMIF(Features!B:B,A30,Features!I:I)
A31: E9 | B31: Customizable Dashboards | C31: User-configurable dashboards with draggable widgets/gadgets | D31: HIGH | E31: TODO | K31: =SUMIF(Features!B:B,A31,Features!I:I)
A32: E10 | B32: Advanced Search & JQL | C32: Jira Query Language-like advanced search with saved filters | D32: HIGH | E32: TODO | K32: =SUMIF(Features!B:B,A32,Features!I:I)

Sheet Features
A1: Feature ID | B1: Epic ID | C1: Feature Name | D1: Description | E1: Acceptance Criteria | F1: Implementation Details | G1: Entities/Classes | H1: Story Count | I1: Story Points (Calculated) | J1: Priority | K1: Status
A2: F1.1 | B2: E1 | C2: Budget Planning & Tracking | D2: Enable project managers to create, monitor and compare budgets against actual costs with variance analysis and alerts. | E2: ✓ Create budgets with categories ✓ Track actual costs from expenses ✓ Calculate variance (planned vs actual) ✓ Visual dashboard with charts ✓ Alert when threshold exceeded | F2: Create CBudgetAnalysisService with calculateActualCosts(), compareBudgetVsActual() methods. Create CComponentBudgetComparison widget extending CComponentBase. Add to CDashboardView. | G2: CBudgetAnalysisService, CComponentBudgetComparison, CDashboardView | H2: 3 | I2: =SUMIF(User_Stories!B:B,A2,User_Stories!F:F) | J2: HIGH | K2: TODO
A3: F1.2 | B3: E1 | C3: Expense & Income Tracking | D3: Complete CRUD for project expenses and incomes with receipt attachments, approval workflow, and export capabilities. | E3: ✓ Log expenses with receipts ✓ Record income from clients ✓ Approval workflow ✓ Export to Excel/PDF ✓ Currency conversion | F3: Enhance existing CProjectExpense, CProjectIncome entities. Create CExcelExportService using Apache POI. Add export buttons to grids. | G3: CProjectExpense, CProjectIncome, CExcelExportService | H3: 3 | I3: =SUMIF(User_Stories!B:B,A3,User_Stories!F:F) | J3: HIGH | K3: PARTIAL
A4: F1.3 | B4: E1 | C4: Multi-Currency Support | D4: Support multiple currencies with automatic conversion, exchange rate management, and consolidated reporting in base currency. | E4: ✓ Define multiple currencies ✓ Set exchange rates ✓ Auto-convert amounts ✓ Show original + converted ✓ Base currency reports | F4: Add exchangeRate field to CCurrency. Create CCurrencyConversionService. Update CBudgetAnalysisService to apply conversions. | G4: CCurrency, CCurrencyConversionService | H4: 2 | I4: =SUMIF(User_Stories!B:B,A4,User_Stories!F:F) | J4: MEDIUM | K4: PARTIAL
A5: F1.4 | B5: E1 | C5: Financial Dashboards & Reports | D5: Executive dashboards showing financial health, cost trends, budget burn rate, and profitability metrics. | E5: ✓ Cost trend charts ✓ Budget burn rate ✓ P&L dashboard ✓ Custom date ranges ✓ Export reports | F5: Create CFinancialDashboardService. Add Vaadin Charts components for visualizations. Create scheduled report generation. | G5: CFinancialDashboardService, CComponentFinancialDashboard | H5: 2 | I5: =SUMIF(User_Stories!B:B,A5,User_Stories!F:F) | J5: MEDIUM | K5: TODO
A6: F2.1 | B6: E2 | C6: Resource Definition & Management | D6: Define and manage resources (people, equipment, facilities) with availability calendars, cost rates, and skills. | E6: ✓ Create resources with types ✓ Set availability calendars ✓ Define cost rates ✓ Manage skills/competencies ✓ Resource pools | F6: Create CResource entity extending CEntityOfCompany. Create CResourceService with validation. Create CRUD views with FormBuilder. | G6: CResource, CResourceType, CResourceService, CResourceView | H6: 2 | I6: =SUMIF(User_Stories!B:B,A6,User_Stories!F:F) | J6: HIGH | K6: TODO
A7: F2.2 | B7: E2 | C7: Resource Allocation & Planning | D7: Assign resources to activities with percentage allocation, view capacity vs allocation, and detect overallocation. | E7: ✓ Assign resources to activities ✓ Set allocation percentage ✓ Capacity vs allocation chart ✓ Overallocation warnings ✓ Resource workload view | F7: Create CResourceAllocation entity. Add @OneToMany to CActivity. Create CComponentListResourceAllocations with selection-aware toolbar. | G7: CResourceAllocation, CResourceAllocationService, CComponentListResourceAllocations | H7: 2 | I7: =SUMIF(User_Stories!B:B,A7,User_Stories!F:F) | J7: HIGH | K7: TODO
A8: F2.3 | B8: E2 | C8: Timesheet Entry & Tracking | D8: Team members enter daily work hours per activity with approval workflow and actual vs planned comparison. | E8: ✓ Weekly timesheet grid ✓ Enter hours per activity ✓ Approval workflow ✓ Actual vs planned ✓ Cost calculation | F8: Create CTimesheet, CTimesheetEntry entities. Create weekly grid view with inline editing. Integrate with CActivity for actual hours. | G8: CTimesheet, CTimesheetEntry, CTimesheetService, CTimesheetView | H8: 3 | I8: =SUMIF(User_Stories!B:B,A8,User_Stories!F:F) | J8: HIGH | K8: TODO
A9: F3.1 | B9: E3 | C9: File Upload & Storage | D9: Secure file upload with metadata, automatic document type detection, and organized file storage. | E9: ✓ Upload files with metadata ✓ Auto-detect document type ✓ Version number tracking ✓ Secure file storage ✓ Download files | F9: DONE: CAttachment, CAttachmentService, CAttachmentStorage implemented with file system storage. | G9: CAttachment, CAttachmentService, CAttachmentStorage | H9: 2 | I9: =SUMIF(User_Stories!B:B,A9,User_Stories!F:F) | J9: CRITICAL | K9: DONE
A10: F3.2 | B10: E3 | C10: Version Control | D10: Track document versions with version history, compare versions, and prevent deletion of documents with newer versions. | E10: ✓ Version chains (previousVersion) ✓ Version history view ✓ Upload new version ✓ Prevent deletion if newer exists ✓ Version comparison | F10: DONE: CAttachment.previousVersion field. getVersionHistory(), uploadNewVersion() methods. Delete validation in service. | G10: CAttachment.previousVersion, CAttachmentService | H10: 2 | I10: =SUMIF(User_Stories!B:B,A10,User_Stories!F:F) | J10: HIGH | K10: DONE
A11: F3.3 | B11: E3 | C11: Integration with Entities | D11: Attach documents to any entity (projects, activities, meetings, etc.) with clean interface-based integration. | E11: ✓ IHasAttachments interface ✓ Attach to any entity ✓ List attachments per entity ✓ Grid component ✓ Double-click edit | F11: DONE: IHasAttachments interface. CComponentListAttachments with selection-aware toolbar, double-click support. | G11: IHasAttachments, CComponentListAttachments | H11: 1 | I11: =SUMIF(User_Stories!B:B,A11,User_Stories!F:F) | J11: HIGH | K11: DONE
A12: F4.1 | B12: E4 | C12: Agile Metrics & Charts | D12: Burndown charts, velocity tracking, cumulative flow diagrams, and sprint metrics for Agile teams. | E12: ✓ Sprint burndown chart ✓ Team velocity chart ✓ Cumulative flow diagram ✓ Lead time analysis ✓ Cycle time tracking | F12: Create CSprintMetricsService with calculateBurndown(), calculateVelocity(). Use Vaadin Charts. Add to sprint detail view. | G12: CSprintMetricsService, CComponentBurndownChart, CComponentVelocityChart | H12: 3 | I12: =SUMIF(User_Stories!B:B,A12,User_Stories!F:F) | J12: HIGH | K12: TODO
A13: F4.2 | B13: E4 | C13: Financial Dashboards | D13: Financial performance dashboards with cost trends, budget tracking, revenue analysis, and P&L reports. | E13: ✓ Project cost dashboard ✓ Portfolio financial summary ✓ Revenue tracking ✓ Cost trends ✓ P&L reports | F13: Create CFinancialDashboardService. Add dashboard widgets to CDashboardView. Support custom date ranges. | G13: CFinancialDashboardService, CComponentFinancialDashboard | H13: 2 | I13: =SUMIF(User_Stories!B:B,A13,User_Stories!F:F) | J13: HIGH | K13: TODO
... A23: F7.3 | B23: E7 | C23: Bug Metrics & Reporting | D23: Bug metrics dashboard showing open/closed rates, resolution time, and bug trends. | E23: ✓ Bug metrics dashboard ✓ Open/closed trends ✓ Resolution time ✓ Bugs by severity ✓ Aging bugs report | F23: Create CTicketMetricsService. Generate charts for bug trends. Add to dashboard. | G23: CTicketMetricsService, CComponentBugMetrics | H23: 2 | I23: =SUMIF(User_Stories!B:B,A23,User_Stories!F:F) | J23: MEDIUM | K23: TODO
A24: F5.1 | B24: E5 | C24: Visual Workflow Designer | D24: Drag-drop workflow canvas with status nodes and transition arrows | E24: HIGH | F24: TODO | I24: =SUMIF(User_Stories!B:B,A24,User_Stories!F:F)
A25: F6.1 | B25: E6 | C25: Issue Link Types | D25: Define link types with forward/reverse names | E25: HIGH | F25: TODO | I25: =SUMIF(User_Stories!B:B,A25,User_Stories!F:F)
A26: F5.1 | B26: E5 | C26: Visual Workflow Designer | D26: Drag-drop canvas for workflow design with status nodes and transition arrows | E26: HIGH | F26: TODO | I26: =SUMIF(User_Stories!B:B,A26,User_Stories!F:F)
A27: F6.1 | B27: E6 | C27: Issue Link Types | D27: Define link types with forward/reverse names (blocks/is blocked by) | E27: HIGH | F27: TODO | I27: =SUMIF(User_Stories!B:B,A27,User_Stories!F:F)
A28: F7.1 | B28: E7 | C28: WIP Limits | D28: Set and enforce work-in-progress limits per column | E28: HIGH | F28: TODO | I28: =SUMIF(User_Stories!B:B,A28,User_Stories!F:F)
A29: F7.2 | B29: E7 | C29: Swimlanes | D29: Group kanban cards by assignee, priority, or project | E29: HIGH | F29: TODO | I29: =SUMIF(User_Stories!B:B,A29,User_Stories!F:F)
A30: F8.1 | B30: E8 | C30: Work Log Entities | D30: Domain model for time tracking | E30: HIGH | F30: TODO | I30: =SUMIF(User_Stories!B:B,A30,User_Stories!F:F)
A31: F9.1 | B31: E9 | C31: Dashboard Framework | D31: Core dashboard and widget architecture | E31: HIGH | F31: TODO | I31: =SUMIF(User_Stories!B:B,A31,User_Stories!F:F)
A32: F10.1 | B32: E10 | C32: JQL Parser | D32: Parse and execute JQL-like queries | E32: HIGH | F32: TODO | I32: =SUMIF(User_Stories!B:B,A32,User_Stories!F:F)

Sheet User_Stories
A1: Story ID | B1: Feature ID | C1: User Story | D1: Acceptance Criteria | E1: Technical Notes | F1: Story Points | G1: Priority | H1: Status | I1: Sprint
A2: US1.1.1 | B2: F1.1 | C2: As a PM, I can create project budgets with multiple categories | D2: Given PM role, When I create budget, Then I can define categories, amounts, and approval thresholds | E2: Use CBudget entity. FormBuilder pattern. Category combobox from CBudgetType. | F2: 5 | G2: HIGH | H2: TODO
A3: US1.1.2 | B3: F1.1 | C3: As a PM, I can view budget vs actual cost comparison dashboard | D3: Given budget exists, When I view dashboard, Then I see planned vs actual with variance percentage | E3: Create CBudgetAnalysisService.compareBudgetVsActual(). Use CGrid with color-coded variance. | F3: 8 | G3: HIGH | H3: TODO
A4: US1.1.3 | B4: F1.1 | C4: As a PM, I receive alerts when budget threshold is exceeded | D4: Given budget threshold, When actual exceeds threshold, Then I receive notification and email | E4: Add @Scheduled check in CBudgetAlertService. Use CNotificationService + email. | F4: 5 | G4: MEDIUM | H4: TODO
A5: US1.2.1 | B5: F1.2 | C5: As a team member, I can log project expenses with receipt attachments | D5: Given team member role, When I log expense, Then I can attach receipt, set category, amount, date | E5: Use CProjectExpense entity. Integrate CAttachment. FormBuilder with file upload. | F5: 5 | G5: HIGH | H5: DONE | I5: Sprint 1
A6: US1.2.2 | B6: F1.2 | C6: As a PM, I can approve/reject expense requests | D6: Given pending expense, When I review, Then I can approve or reject with comments | E6: Add approval workflow to CProjectExpense. IHasStatusAndWorkflow interface. | F6: 3 | G6: HIGH | H6: DONE | I6: Sprint 1
A7: US1.2.3 | B7: F1.2 | C7: As an accountant, I can export financial data to Excel | D7: Given financial data, When I click export, Then I download XLSX with all expenses/incomes | E7: Create CExcelExportService using Apache POI. Add export button to grids. | F7: 8 | G7: MEDIUM | H7: TODO
A8: US2.1.1 | B8: F2.1 | C8: As an admin, I can define resources (people, equipment, facilities) | D8: Given admin role, When I create resource, Then I set type, availability, cost rate | E8: Create CResource entity extending CEntityOfCompany. CResourceService with validation. | F8: 5 | G8: HIGH | H8: TODO
A9: US2.1.2 | B9: F2.1 | C9: As an admin, I can set resource availability calendars | D9: Given resource, When I set availability, Then I define working hours, holidays, leave | E9: Add CResourceCalendar entity. Link to CResource. Calendar UI component. | F9: 6 | G9: MEDIUM | H9: TODO
A10: US2.2.1 | B10: F2.2 | C10: As a PM, I can assign resources to activities with % allocation | D10: Given activity, When I assign resource, Then I set allocation %, start date, end date | E10: Create CResourceAllocation entity. Master-detail with CActivity. Grid component. | F10: 5 | G10: HIGH | H10: TODO
A11: US2.2.2 | B11: F2.2 | C11: As a PM, I can view resource capacity vs allocation chart | D11: Given resources, When I view chart, Then I see capacity bars vs allocation bars | E11: Create CResourceCapacityService. Use Vaadin Charts. Add to dashboard. | F11: 7 | G11: MEDIUM | H11: TODO
A12: US3.1.1 | B12: F3.1 | C12: As a user, I can upload files with automatic type detection | D12: Given file, When I upload, Then system detects document type from extension | E12: DONE: CDocumentTypeService.detectDocumentType(). Auto-sets on upload. | F12: 3 | G12: HIGH | H12: DONE | I12: Sprint 1
A13: US3.1.2 | B13: F3.1 | C13: As a user, I can download attached files | D13: Given attachment, When I click download, Then file downloads with original name | E13: DONE: CAttachmentService.downloadFile(). StreamResource pattern. | F13: 2 | G13: HIGH | H13: DONE | I13: Sprint 1
A14: US3.2.1 | B14: F3.2 | C14: As a user, I can upload new version of existing document | D14: Given document, When I upload new version, Then version number increments | E14: DONE: CAttachmentService.uploadNewVersion(). Links previousVersion. | F14: 5 | G14: HIGH | H14: DONE | I14: Sprint 2
A15: US3.2.2 | B15: F3.2 | C15: As a user, I can view version history of a document | D15: Given document, When I view history, Then I see all versions with dates | E15: DONE: CAttachment.getVersionHistory(). Traverse version chain. | F15: 3 | G15: MEDIUM | H15: DONE | I15: Sprint 2
A16: US4.1.1 | B16: F4.1 | C16: As a Scrum Master, I can view sprint burndown chart | D16: Given sprint, When I view metrics, Then I see daily story point burndown vs ideal | E16: Create CSprintMetricsService.calculateBurndown(). Vaadin Charts line chart. | F16: 5 | G16: HIGH | H16: TODO
A17: US4.1.2 | B17: F4.1 | C17: As a PM, I can view team velocity over multiple sprints | D17: Given sprints, When I view velocity, Then I see completed story points per sprint | E17: Create CSprintMetricsService.calculateVelocity(). Bar chart with trend line. | F17: 4 | G17: HIGH | H17: TODO
A18: US1.3.1 | B18: F1.3 | C18: As an admin, I can define multiple currencies for the company | D18: Given admin role, When I add currency, Then I set code, symbol, exchange rate | E18: Use CCurrency entity (already exists). Add CRUD UI if missing. | F18: 2 | G18: MEDIUM | H18: PARTIAL
A19: US1.3.2 | B19: F1.3 | C19: As a PM, I can see expenses in multiple currencies with auto-conversion | D19: Given expenses in different currencies, When I view list, Then I see original + converted to base currency | E19: Use CCurrencyConversionService. Add calculated column to grids. | F19: 3 | G19: MEDIUM | H19: TODO
A20: US1.4.1 | B20: F1.4 | C20: As a PM, I can view cost trend chart over time | D20: Given project, When I view financial dashboard, Then I see line chart of costs over months | E20: Create CFinancialDashboardService. Use Vaadin Charts. Group by month. | F20: 3 | G20: MEDIUM | H20: TODO
A21: US1.4.2 | B21: F1.4 | C21: As an exec, I can view P&L dashboard for all projects | D21: Given portfolio, When I view P&L, Then I see income vs expenses with profit/loss | E21: Aggregate across projects. Create CComponentProfitLoss widget. | F21: 4 | G21: MEDIUM | H21: TODO
A22: US2.3.3 | B22: F2.3 | C22: As a manager, I can approve/reject timesheets | D22: Given submitted timesheet, When I review, Then I can approve or reject with comments | E22: Add approval workflow. Manager role check. Status transitions. | F22: 3 | G22: HIGH | H22: TODO
A23: US4.2.1 | B23: F4.2 | C23: As a PM, I can view project cost dashboard with charts | D23: Given project, When I view cost dashboard, Then I see total cost, cost breakdown by category, trend | E23: Create CProjectCostDashboard. Use Vaadin Charts for pie and line charts. | F23: 5 | G23: HIGH | H23: TODO
A24: US4.2.2 | B24: F4.2 | C24: As a CFO, I can view portfolio financial summary | D24: Given portfolio, When I view summary, Then I see aggregated costs, revenues, profits across all projects | E24: Aggregate financials across portfolio. Create CPortfolioFinancialSummary. | F24: 5 | G24: HIGH | H24: TODO
A25: US4.3.1 | B25: F4.3 | C25: As a PM, I can view resource utilization report | D25: Given date range, When I view report, Then I see each resource with hours allocated, available, utilization % | E25: Create CResourceUtilizationReport. Calculate from CResourceAllocation + CTimesheet. | F25: 4 | G25: MEDIUM | H25: TODO
A26: US4.3.2 | B26: F4.3 | C26: As a PM, I can export resource report to Excel | D26: Given resource report, When I click export, Then I download XLSX with all data | E26: Use CExcelExportService. Format as table with conditional formatting. | F26: 3 | G26: MEDIUM | H26: TODO
A27: US4.4.1 | B27: F4.4 | C27: As an admin, I can create custom report definitions | D27: Given report builder, When I define report, Then I select entity, columns, filters, grouping | E27: Create CReport entity. Report builder UI with query construction. | F27: 5 | G27: LOW | H27: TODO
... A33: US7.3.1 | B33: F7.3 | C33: As a PM, I can view aging bugs report | D33: Given project, When I view aging report, Then I see bugs sorted by days open, highlight stale bugs | E33: Calculate days since created. Color-code: >30 days red, 15-30 yellow. | F33: 2 | G33: LOW | H33: TODO
A34: US5.1.1 | B34: F5.1 | C34: Workflow canvas component | D34: As admin, I can design workflows visually with drag-drop | E34: TODO | F34: 13
A35: US6.1.1 | B35: F6.1 | C35: Link type management | D35: As admin, I can create link types (blocks/is blocked by) | E35: TODO | F35: 8
A36: US5.1.1 | B36: F5.1 | C36: Workflow entities | D36: As developer, entities exist for workflow statuses and transitions | E36: TODO | F36: 8
A37: US5.1.2 | B37: F5.1 | C37: Workflow services | D37: As developer, services exist for workflow CRUD and transition logic | E37: TODO | F37: 8
A38: US5.1.3 | B38: F5.1 | C38: Workflow designer UI | D38: As admin, I can design workflows visually in canvas | E38: TODO | F38: 13
A39: US6.1.1 | B39: F6.1 | C39: Link type management | D39: As admin, I can create and manage issue link types | E39: TODO | F39: 5
A40: US6.1.2 | B40: F6.1 | C40: Link management UI | D40: As user, I can add/remove links between issues | E40: TODO | F40: 8
A41: US7.1.1 | B41: F7.1 | C41: WIP limit configuration | D41: As admin, I can set WIP limits on kanban columns | E41: TODO | F41: 5
A42: US7.2.1 | B42: F7.2 | C42: Swimlane implementation | D42: As user, I can view kanban board with swimlanes | E42: TODO | F42: 8
A43: US8.1.1 | B43: F8.1 | C43: Worklog entities | D43: As developer, worklog entities exist | E43: TODO | F43: 5
A44: US8.1.2 | B44: F8.1 | C44: Worklog UI components | D44: As user, I can log time on issues | E44: TODO | F44: 8
A45: US9.1.1 | B45: F9.1 | C45: Dashboard entities | D45: As developer, dashboard entities exist | E45: TODO | F45: 5
...

Sheet Tasks
A1: Task ID | B1: Story ID | C1: Task Description | D1: Technical Implementation | E1: Coding Standards Applied | F1: Files to Create/Modify | G1: Story Points | H1: Status | I1: Assignee
A2: T1.1.1.1 | B2: US1.1.1 | C2: Create budget category selection in form | D2: Add CBudgetType combobox to budget creation form using FormBuilder | E2: ✓ Use @AMetaData dataProviderBean="CBudgetTypeService" ✓ ComboBox with entity column ✓ Required field validation | F2: CBudget entity, CDialogBudget | G2: 2 | H2: DONE
A3: T1.1.2.1 | B3: US1.1.2 | C3: Create CBudgetAnalysisService | D3: Service with calculateActualCosts(CProject) returning Map<CBudget, BigDecimal> and compareBudgetVsActual(CProject) returning List<BudgetComparison> | E3: ✓ Extend CAbstractService ✓ Constructor injection ✓ @Transactional(readOnly=true) ✓ Stateless (no instance user state) ✓ Use Objects.requireNonNull() for validation | F3: src/.../budgets/service/CBudgetAnalysisService.java src/.../budgets/dto/BudgetComparison.java | G3: 3 | H3: TODO
A4: T1.1.2.2 | B4: US1.1.2 | C4: Create CComponentBudgetComparison widget | D4: Dashboard widget with CGrid showing budget name, planned amount, actual amount, variance (actual-planned), percentage (actual/planned*100). Color-code rows: green <80%, yellow 80-100%, red >100% | E4: ✓ Extend CComponentBase ✓ Use CGrid<BudgetComparison> ✓ addColumn for each field ✓ Custom cell renderer for variance color ✓ Currency formatting for amounts ✓ Percentage formatting | F4: src/.../budgets/view/CComponentBudgetComparison.java | G4: 3 | H4: TODO
A5: T1.1.2.3 | B5: US1.1.2 | C5: Integrate widget into CDashboardView | D5: Add budget comparison widget to main dashboard, project detail view, and financial summary tab | E5: ✓ Instantiate CComponentBudgetComparison ✓ Pass project parameter ✓ Add to layout ✓ Register refresh listeners | F5: src/.../dashboard/CDashboardView.java src/.../projects/view/CProjectDetailView.java | G5: 2 | H5: TODO
A6: T1.1.3.1 | B6: US1.1.3 | C6: Add budget threshold field to CBudget | D6: Add alertThresholdPercentage field (default 80%) to trigger alerts when actual > threshold | E6: ✓ @Column(name="alert_threshold_percentage") ✓ @AMetaData annotation ✓ Default value 80 ✓ Validation 0-100 range | F6: src/.../budgets/domain/CBudget.java | G6: 1 | H6: TODO
A7: T1.1.3.2 | B7: US1.1.3 | C7: Create CBudgetAlertService with scheduled check | D7: Service with @Scheduled method checking budgets every hour, sending notifications when threshold exceeded | E7: ✓ @Service annotation ✓ @Scheduled(cron="0 0 * * * ?") ✓ Query budgets with exceeded threshold ✓ Use CNotificationService ✓ Send email via CEmailNotificationService | F7: src/.../budgets/service/CBudgetAlertService.java | G7: 4 | H7: TODO
A8: T1.2.1.1 | B8: US1.2.1 | C8: Add receipt attachment to expense form | D8: Integrate IHasAttachments pattern into CProjectExpense, add attachment button to form | E8: ✓ CProjectExpense implements IHasAttachments ✓ Add attachment list component to form ✓ Upload receipt on expense creation | F8: src/.../projectexpenses/domain/CProjectExpense.java src/.../projectexpenses/view/CDialogProjectExpense.java | G8: 2 | H8: DONE
A9: T1.2.2.1 | B9: US1.2.2 | C9: Add approval workflow to CProjectExpense | D9: Implement IHasStatusAndWorkflow, create expense approval workflow with states: DRAFT, PENDING, APPROVED, REJECTED | E9: ✓ Implement IHasStatusAndWorkflow ✓ Create CProjectExpenseWorkflow ✓ Approval states in workflow ✓ Approval actions in service | F9: src/.../projectexpenses/domain/CProjectExpense.java src/.../projectexpenses/domain/CProjectExpenseWorkflow.java | G9: 3 | H9: PARTIAL
A10: T1.2.3.1 | B10: US1.2.3 | C10: Add Apache POI dependency to pom.xml | D10: Add Apache POI 5.2+ dependency for Excel generation | E10: ✓ Add dependency to pom.xml ✓ Include poi-ooxml for XLSX support | F10: pom.xml | G10: 1 | H10: TODO
A11: T1.2.3.2 | B11: US1.2.3 | C11: Create CExcelExportService | D11: Service to export expenses/incomes to XLSX with formatting, formulas, and charts | E11: ✓ Create Workbook with XSSFWorkbook ✓ Apply cell styles (headers, currency) ✓ Add formulas for totals ✓ Return StreamResource for download ✓ Set filename with timestamp | F11: src/.../reports/service/CExcelExportService.java | G11: 5 | H11: TODO
A12: T1.2.3.3 | B12: US1.2.3 | C12: Add export buttons to expense/income grids | D12: Add CButton with VaadinIcon.DOWNLOAD to toolbar, trigger export on click | E12: ✓ Create buttonExport with CButton ✓ on_buttonExport_clicked() handler ✓ Call exportService.exportExpenses() ✓ Trigger download with StreamResource ✓ Show success notification | F12: src/.../projectexpenses/view/CProjectExpenseView.java src/.../projectincomes/view/CProjectIncomeView.java | G12: 2 | H12: TODO
A13: T1.3.1.1 | B13: US1.3.1 | C13: Add exchangeRate field to CCurrency | D13: Add exchange rate to base currency field with validation | E13: ✓ @Column(name="exchange_rate", precision=10, scale=6) ✓ BigDecimal type ✓ @AMetaData annotation ✓ Positive value validation | F13: src/.../api/domain/CCurrency.java | G13: 1 | H13: TODO
... A91: T10.1.2.3 | B91: US10.1.2 | C91: Create CSavedFilter entity and management | D91: AI: 1) Entity: CSavedFilter with name, jql, owner, isShared 2) Service: CSavedFilterService 3) Dialog: CDialogSaveFilter 4) Component: CComponentSavedFilters (list favorites) | E91: ✓ C-prefix class ✓ Extend CEntity* ✓ ENTITY_TITLE constants ✓ Logger ✓ @AMetaData ✓ Validations ✓ LAZY fetch ✓ equals/hashCode on id ✓ C-prefix ✓ Extend CAbstractService ✓ @Service ✓ Constructor injection ✓ @Transactional ✓ Objects.requireNonNull ✓ Stateless ✓ CAbstract*Page ✓ C-components ✓ typeName fields ✓ on_x_y handlers ✓ create_x factories ✓ No lambdas ✓ CNotificationService ✓ Grid refresh | F91: CREATE: domain/CSavedFilter.java, services/CSavedFilterService.java, ui/CDialogSaveFilter.java | G91: 5 | H91: TODO

Sheet Storypoint_Methodology
A1: Story Point Estimation Methodology
A2: Range (approx. words) | B2: Story Points | C2: Rationale
A3: ≤ 50 words | B3: 1 SP | C3: Simple tasks requiring straightforward coding or minor configuration changes; minimal debugging or refactoring needed.
A4: 51–100 words | B4: 2 SP | C4: Moderate tasks involving creation of entities, services or UI components, plus some design thinking and basic testing.
A5: 101–150 words | B5: 3 SP | C5: Complex tasks spanning multiple components (entity, service, UI) or involving calculations and conditional logic; may need refactoring.
A6: > 150 words | B6: 5 SP | C6: Very complex tasks or features spanning several modules requiring significant coding, debugging, integration and risk of refactoring.
A8: Guidance: | C8: When estimating story points, consider not just the coding effort but also the time for analysis, testing, debugging, documentation and potential refactoring. Tasks estimated above five story points should be split into smaller tasks to fit within a 2–3 day sprint window. These estimates are approximate and should be reviewed by the team.
